Workbook
Name Slicer_borrowerbank: #N/A
Name Slicer_borrowervintagetier: #N/A
Name Slicer_employmentstatus: #N/A

Sheet Risk_Diagnostics_Hub
A1: repaymentstatusflag | B1: (All)
A2: The Banking Ecosystem Risk Test | E2: The Income & Employment Stability Test
A3: Row Labels | B3: NPL Ratio | E3: Row Labels | F3: Average of repaymentstatusflag
A4: Access Bank | B4: 0.23780488 | F4: 0.30425963 | J4: Total Capital Disbursed
A5: Diamond Bank | B5: 0.14351852 | E5: Contract | F5: 0 | J5: 77790000
A6: EcoBank | B6: 0.25862069 | E6: Permanent | F6: 0.20555556
A7: FCMB | B7: 0.25842697 | E7: Retired | F7: 0
A8: Fidelity Bank | B8: 0.22972973 | E8: Self-Employed | F8: 0.16245487 | J8: PORTFOLIO AT RISK (BAD LOANS)
A9: First Bank | B9: 0.22093023 | E9: Student | F9: 0.27027027 | J9: 952
A10: GT Bank | B10: 0.21623861 | E10: Unemployed | F10: 0.1627907
A11: Heritage Bank | B11: 0.16666667 | E11: Unknown Status | F11: 0.21747043
A12: Keystone Bank | B12: 0.21428571 | E12: Grand Total | F12: 0.21794872 | J12: Average of repaymentstatusflag
A13: Skye Bank | B13: 0.28 | J13: 0.21794872
A14: Stanbic IBTC | B14: 0.15384615
A15: Standard Chartered | B15: 0.076923077 | E15: The Pricing Appetite Test
A16: Sterling Bank | B16: 0.35714286 | E16: interest markup | F16: Badloans(count) | G16: NPL Ratio
A17: UBA | B17: 0.22846442 | E17: 0 | F17: 0 | G17: 0
A18: Union Bank | B18: 0.13333333 | E18: 0.025 | F18: 0 | G18: 0
A19: Unity Bank | B19: 0.2 | E19: 0.045 | F19: 0 | G19: 0
A20: Unspecified Bank | B20: 0.21747043 | E20: 0.05 | F20: 1 | G20: 0.021276596
A21: Wema Bank | B21: 0.10526316 | E21: 0.075 | F21: 1 | G21: 0.04
A22: Zenith Bank | B22: 0.22767857 | E22: 0.0875 | F22: 2 | G22: 0.28571429
A23: Grand Total | B23: 0.21794872 | E23: 0.09 | F23: 0 | G23: 0
E24: 0.1 | F24: 29 | G24: 0.097972973
E25: 0.1125 | F25: 33 | G25: 0.19186047
E26: 0.13333 | F26: 0 | G26: 0
A27: The Vintage Loyalty Test (Borrower Velocity) | E27: 0.135 | F27: 1 | G27: 0.25
A28: Row Labels | B28: NPL Ratio | E28: 0.14001 | F28: 0 | G28: 0
A29: 2. Early Repeat (2-3) | B29: 0.25496849 | E29: 0.15 | F29: 242 | G29: 0.20066335
A30: 3. High Velocity Loyalty (4+) | B30: 0.18481562 | E30: 0.2 | F30: 28 | G30: 0.20437956
A31: Grand Total | B31: 0.21794872 | E31: 0.225 | F31: 104 | G31: 0.15568862
E32: 0.25 | F32: 3 | G32: 0.21428571
E33: 0.28334 | F33: 0 | G33: 0
E34: 0.3 | F34: 508 | G34: 0.28603604
E35: Grand Total | F35: 952 | G35: 0.21794872

Sheet Master_Loan_Book
A1: customerid | B1: systemloanid | C1: loannumber | D1: approveddate | E1: creationdate | F1: loanamount | G1: totaldue | H1: termdays | I1: referredby | J1: good_bad_flag | K1: interestmarkup(%) | L1: repaymentstatusflag | M1: borrowervintagetier | N1: borrowerbank | O1: employmentstatus
A2: 8a2a81a74ce8c05d014cfb32a0da1049 | B2: 301994762 | C2: 12 | D2: 42941.349 | E2: 42941.307 | F2: 30000 | G2: 34500 | H2: 30 | J2: Good | K2: =(G2 - F2) / F2 -> 0.15 | L2: =IF(J2="bad", 1, 0) -> 0 | M2: =IF(C2=1, "1. First-Time Applicant", IF(C2<=3, "2. Early Repeat (2-3)", "3. High Velocity Loyalty (4+)")) -> 3. High Velocity Loyalty (4+) | N2: =IFERROR(INDEX(Demographics!F:F, MATCH(A2, Demographics!A:A, 0)), "Unspecified Bank") -> Diamond Bank | O2: =IFERROR(INDEX(Demographics!H:H, MATCH(A2, Demographics!A:A, 0)) & "", "Unknown Status") -> Permanent
A3: 8a85886e54beabf90154c0a29ae757c0 | B3: 301965204 | C3: 2 | D3: 42921.712 | E3: 42921.67 | F3: 15000 | G3: 17250 | H3: 30 | J3: Good | K3: =(G3 - F3) / F3 -> 0.15 | L3: =IF(J3="bad", 1, 0) -> 0 | M3: =IF(C3=1, "1. First-Time Applicant", IF(C3<=3, "2. Early Repeat (2-3)", "3. High Velocity Loyalty (4+)")) -> 2. Early Repeat (2-3) | N3: =IFERROR(INDEX(Demographics!F:F, MATCH(A3, Demographics!A:A, 0)), "Unspecified Bank") -> GT Bank | O3: =IFERROR(INDEX(Demographics!H:H, MATCH(A3, Demographics!A:A, 0)) & "", "Unknown Status") -> Permanent
A4: 8a8588f35438fe12015444567666018e | B4: 301966580 | C4: 7 | D4: 42922.62 | E4: 42922.578 | F4: 20000 | G4: 22250 | H4: 15 | J4: Good | K4: =(G4 - F4) / F4 -> 0.1125 | L4: =IF(J4="bad", 1, 0) -> 0 | M4: =IF(C4=1, "1. First-Time Applicant", IF(C4<=3, "2. Early Repeat (2-3)", "3. High Velocity Loyalty (4+)")) -> 3. High Velocity Loyalty (4+) | N4: =IFERROR(INDEX(Demographics!F:F, MATCH(A4, Demographics!A:A, 0)), "Unspecified Bank") -> EcoBank | O4: =IFERROR(INDEX(Demographics!H:H, MATCH(A4, Demographics!A:A, 0)) & "", "Unknown Status") -> Permanent
A5: 8a85890754145ace015429211b513e16 | B5: 301999343 | C5: 3 | D5: 42943.792 | E5: 42943.75 | F5: 10000 | G5: 11500 | H5: 15 | J5: Good | K5: =(G5 - F5) / F5 -> 0.15 | L5: =IF(J5="bad", 1, 0) -> 0 | M5: =IF(C5=1, "1. First-Time Applicant", IF(C5<=3, "2. Early Repeat (2-3)", "3. High Velocity Loyalty (4+)")) -> 2. Early Repeat (2-3) | N5: =IFERROR(INDEX(Demographics!F:F, MATCH(A5, Demographics!A:A, 0)), "Unspecified Bank") -> First Bank | O5: =IFERROR(INDEX(Demographics!H:H, MATCH(A5, Demographics!A:A, 0)) & "", "Unknown Status") -> Permanent
A6: 8a858970548359cc0154883481981866 | B6: 301962360 | C6: 9 | D6: 42919.988 | E6: 42919.946 | F6: 40000 | G6: 44000 | H6: 30 | J6: Good | K6: =(G6 - F6) / F6 -> 0.1 | L6: =IF(J6="bad", 1, 0) -> 0 | M6: =IF(C6=1, "1. First-Time Applicant", IF(C6<=3, "2. Early Repeat (2-3)", "3. High Velocity Loyalty (4+)")) -> 3. High Velocity Loyalty (4+) | N6: =IFERROR(INDEX(Demographics!F:F, MATCH(A6, Demographics!A:A, 0)), "Unspecified Bank") -> GT Bank | O6: =IFERROR(INDEX(Demographics!H:H, MATCH(A6, Demographics!A:A, 0)) & "", "Unknown Status") -> Permanent
A7: 8a8589f35451855401546b0738c42524 | B7: 301986516 | C7: 8 | D7: 42935.907 | E7: 42935.865 | F7: 30000 | G7: 39000 | H7: 60 | J7: Good | K7: =(G7 - F7) / F7 -> 0.3 | L7: =IF(J7="bad", 1, 0) -> 0 | M7: =IF(C7=1, "1. First-Time Applicant", IF(C7<=3, "2. Early Repeat (2-3)", "3. High Velocity Loyalty (4+)")) -> 3. High Velocity Loyalty (4+) | N7: =IFERROR(INDEX(Demographics!F:F, MATCH(A7, Demographics!A:A, 0)), "Unspecified Bank") -> Unspecified Bank | O7: =IFERROR(INDEX(Demographics!H:H, MATCH(A7, Demographics!A:A, 0)) & "", "Unknown Status") -> Unknown Status
A8: 8a858e095c59b91b015c5e5cea3719bc | B8: 301972027 | C8: 3 | D8: 42926.809 | E8: 42926.768 | F8: 10000 | G8: 13000 | H8: 30 | J8: Good | K8: =(G8 - F8) / F8 -> 0.3 | L8: =IF(J8="bad", 1, 0) -> 0 | M8: =IF(C8=1, "1. First-Time Applicant", IF(C8<=3, "2. Early Repeat (2-3)", "3. High Velocity Loyalty (4+)")) -> 2. Early Repeat (2-3) | N8: =IFERROR(INDEX(Demographics!F:F, MATCH(A8, Demographics!A:A, 0)), "Unspecified Bank") -> GT Bank | O8: =IFERROR(INDEX(Demographics!H:H, MATCH(A8, Demographics!A:A, 0)) & "", "Unknown Status") -> Permanent
A9: 8a858e1158dc4d830158f7bde4f47ea7 | B9: 301994428 | C9: 10 | D9: 42940.988 | E9: 42940.946 | F9: 30000 | G9: 34500 | H9: 30 | J9: Good | K9: =(G9 - F9) / F9 -> 0.15 | L9: =IF(J9="bad", 1, 0) -> 0 | M9: =IF(C9=1, "1. First-Time Applicant", IF(C9<=3, "2. Early Repeat (2-3)", "3. High Velocity Loyalty (4+)")) -> 3. High Velocity Loyalty (4+) | N9: =IFERROR(INDEX(Demographics!F:F, MATCH(A9, Demographics!A:A, 0)), "Unspecified Bank") -> First Bank | O9: =IFERROR(INDEX(Demographics!H:H, MATCH(A9, Demographics!A:A, 0)) & "", "Unknown Status")
A10: 8a858e185b4923b4015b4ae48d28646a | B10: 301996687 | C10: 4 | D10: 42942.454 | E10: 42942.412 | F10: 10000 | G10: 11500 | H10: 15 | J10: Good | K10: =(G10 - F10) / F10 -> 0.15 | L10: =IF(J10="bad", 1, 0) -> 0 | M10: =IF(C10=1, "1. First-Time Applicant", IF(C10<=3, "2. Early Repeat (2-3)", "3. High Velocity Loyalty (4+)")) -> 3. High Velocity Loyalty (4+) | N10: =IFERROR(INDEX(Demographics!F:F, MATCH(A10, Demographics!A:A, 0)), "Unspecified Bank") -> GT Bank | O10: =IFERROR(INDEX(Demographics!H:H, MATCH(A10, Demographics!A:A, 0)) & "", "Unknown Status") -> Permanent
A11: 8a858e1d5cd58f9e015ceda4bdb63673 | B11: 301981931 | C11: 2 | D11: 42933.575 | E11: 42933.534 | F11: 10000 | G11: 11500 | H11: 15 | J11: Good | K11: =(G11 - F11) / F11 -> 0.15 | L11: =IF(J11="bad", 1, 0) -> 0 | M11: =IF(C11=1, "1. First-Time Applicant", IF(C11<=3, "2. Early Repeat (2-3)", "3. High Velocity Loyalty (4+)")) -> 2. Early Repeat (2-3) | N11: =IFERROR(INDEX(Demographics!F:F, MATCH(A11, Demographics!A:A, 0)), "Unspecified Bank") -> Access Bank | O11: =IFERROR(INDEX(Demographics!H:H, MATCH(A11, Demographics!A:A, 0)) & "", "Unknown Status") -> Unemployed
A12: 8a858e245c214660015c2ba8187976f7 | B12: 301962365 | C12: 2 | D12: 42919.992 | E12: 42919.951 | F12: 10000 | G12: 13000 | H12: 30 | J12: Good | K12: =(G12 - F12) / F12 -> 0.3 | L12: =IF(J12="bad", 1, 0) -> 0 | M12: =IF(C12=1, "1. First-Time Applicant", IF(C12<=3, "2. Early Repeat (2-3)", "3. High Velocity Loyalty (4+)")) -> 2. Early Repeat (2-3) | N12: =IFERROR(INDEX(Demographics!F:F, MATCH(A12, Demographics!A:A, 0)), "Unspecified Bank") -> EcoBank | O12: =IFERROR(INDEX(Demographics!H:H, MATCH(A12, Demographics!A:A, 0)) & "", "Unknown Status") -> Permanent
A13: 8a858e345bd96da8015be6b9f8bc10c7 | B13: 301960371 | C13: 3 | D13: 42918.916 | E13: 42918.874 | F13: 10000 | G13: 13000 | H13: 30 | J13: Bad | K13: =(G13 - F13) / F13 -> 0.3 | L13: =IF(J13="bad", 1, 0) -> 1 | M13: =IF(C13=1, "1. First-Time Applicant", IF(C13<=3, "2. Early Repeat (2-3)", "3. High Velocity Loyalty (4+)")) -> 2. Early Repeat (2-3) | N13: =IFERROR(INDEX(Demographics!F:F, MATCH(A13, Demographics!A:A, 0)), "Unspecified Bank") -> GT Bank | O13: =IFERROR(INDEX(Demographics!H:H, MATCH(A13, Demographics!A:A, 0)) & "", "Unknown Status") -> Permanent
... A18: 8a858e645755e62201576b58e3522081 | B18: 301958834 | C18: 3 | D18: 42917.49 | E18: 42917.448 | F18: 10000 | G18: 11500 | H18: 15 | J18: Good | K18: =(G18 - F18) / F18 -> 0.15 | L18: =IF(J18="bad", 1, 0) -> 0 | M18: =IF(C18=1, "1. First-Time Applicant", IF(C18<=3, "2. Early Repeat (2-3)", "3. High Velocity Loyalty (4+)")) -> 2. Early Repeat (2-3) | N18: =IFERROR(INDEX(Demographics!F:F, MATCH(A18, Demographics!A:A, 0)), "Unspecified Bank") -> UBA | O18: =IFERROR(INDEX(Demographics!H:H, MATCH(A18, Demographics!A:A, 0)) & "", "Unknown Status") -> Permanent
A19: 8a858e6c5bd3fbff015bd408ac3e067a | B19: 301993535 | C19: 2 | D19: 42940.609 | E19: 42940.567 | F19: 10000 | G19: 11500 | H19: 15 | I19: 8a858ef458d4a52e0158d858eb5d6456 | J19: Bad | K19: =(G19 - F19) / F19 -> 0.15 | L19: =IF(J19="bad", 1, 0) -> 1 | M19: =IF(C19=1, "1. First-Time Applicant", IF(C19<=3, "2. Early Repeat (2-3)", "3. High Velocity Loyalty (4+)")) -> 2. Early Repeat (2-3) | N19: =IFERROR(INDEX(Demographics!F:F, MATCH(A19, Demographics!A:A, 0)), "Unspecified Bank") -> GT Bank | O19: =IFERROR(INDEX(Demographics!H:H, MATCH(A19, Demographics!A:A, 0)) & "", "Unknown Status")
A20: 8a858e705668e16701567f1523211e5a | B20: 301985106 | C20: 15 | D20: 42935.346 | E20: 42935.304 | F20: 40000 | G20: 44000 | H20: 30 | J20: Good | K20: =(G20 - F20) / F20 -> 0.1 | L20: =IF(J20="bad", 1, 0) -> 0 | M20: =IF(C20=1, "1. First-Time Applicant", IF(C20<=3, "2. Early Repeat (2-3)", "3. High Velocity Loyalty (4+)")) -> 3. High Velocity Loyalty (4+) | N20: =IFERROR(INDEX(Demographics!F:F, MATCH(A20, Demographics!A:A, 0)), "Unspecified Bank") -> Diamond Bank | O20: =IFERROR(INDEX(Demographics!H:H, MATCH(A20, Demographics!A:A, 0)) & "", "Unknown Status") -> Permanent
A21: 8a858e7d595026f8015951c0c4a03fae | B21: 301959458 | C21: 10 | D21: 42917.91 | E21: 42917.868 | F21: 30000 | G21: 34500 | H21: 30 | J21: Good | K21: =(G21 - F21) / F21 -> 0.15 | L21: =IF(J21="bad", 1, 0) -> 0 | M21: =IF(C21=1, "1. First-Time Applicant", IF(C21<=3, "2. Early Repeat (2-3)", "3. High Velocity Loyalty (4+)")) -> 3. High Velocity Loyalty (4+) | N21: =IFERROR(INDEX(Demographics!F:F, MATCH(A21, Demographics!A:A, 0)), "Unspecified Bank") -> Diamond Bank | O21: =IFERROR(INDEX(Demographics!H:H, MATCH(A21, Demographics!A:A, 0)) & "", "Unknown Status") -> Permanent
A22: 8a858e885c17687c015c19eead6338fd | B22: 301964283 | C22: 3 | D22: 42921.315 | E22: 42921.274 | F22: 10000 | G22: 13000 | H22: 30 | I22: 8a858ff85bd93919015bda56605652bd | J22: Good | K22: =(G22 - F22) / F22 -> 0.3 | L22: =IF(J22="bad", 1, 0) -> 0 | M22: =IF(C22=1, "1. First-Time Applicant", IF(C22<=3, "2. Early Repeat (2-3)", "3. High Velocity Loyalty (4+)")) -> 2. Early Repeat (2-3) | N22: =IFERROR(INDEX(Demographics!F:F, MATCH(A22, Demographics!A:A, 0)), "Unspecified Bank") -> GT Bank | O22: =IFERROR(INDEX(Demographics!H:H, MATCH(A22, Demographics!A:A, 0)) & "", "Unknown Status") -> Permanent
A23: 8a858e8f5d41c974015d4b7f31865627 | B23: 302003432 | C23: 2 | D23: 42946.56 | E23: 42946.518 | F23: 10000 | G23: 11500 | H23: 15 | I23: 8a858e495d1e235c015d30d5ddb42149 | J23: Bad | K23: =(G23 - F23) / F23 -> 0.15 | L23: =IF(J23="bad", 1, 0) -> 1 | M23: =IF(C23=1, "1. First-Time Applicant", IF(C23<=3, "2. Early Repeat (2-3)", "3. High Velocity Loyalty (4+)")) -> 2. Early Repeat (2-3) | N23: =IFERROR(INDEX(Demographics!F:F, MATCH(A23, Demographics!A:A, 0)), "Unspecified Bank") -> First Bank | O23: =IFERROR(INDEX(Demographics!H:H, MATCH(A23, Demographics!A:A, 0)) & "", "Unknown Status") -> Permanent
A24: 8a858e9b5a195041015a1a602a51519d | B24: 301976439 | C24: 7 | D24: 42929.735 | E24: 42929.693 | F24: 25000 | G24: 28750 | H24: 30 | J24: Good | K24: =(G24 - F24) / F24 -> 0.15 | L24: =IF(J24="bad", 1, 0) -> 0 | M24: =IF(C24=1, "1. First-Time Applicant", IF(C24<=3, "2. Early Repeat (2-3)", "3. High Velocity Loyalty (4+)")) -> 3. High Velocity Loyalty (4+) | N24: =IFERROR(INDEX(Demographics!F:F, MATCH(A24, Demographics!A:A, 0)), "Unspecified Bank") -> GT Bank | O24: =IFERROR(INDEX(Demographics!H:H, MATCH(A24, Demographics!A:A, 0)) & "", "Unknown Status")
A25: 8a858ea555d9e6020155f489c9b237f8 | B25: 301973446 | C25: 3 | D25: 42927.724 | E25: 42927.682 | F25: 10000 | G25: 13000 | H25: 30 | J25: Good | K25: =(G25 - F25) / F25 -> 0.3 | L25: =IF(J25="bad", 1, 0) -> 0 | M25: =IF(C25=1, "1. First-Time Applicant", IF(C25<=3, "2. Early Repeat (2-3)", "3. High Velocity Loyalty (4+)")) -> 2. Early Repeat (2-3) | N25: =IFERROR(INDEX(Demographics!F:F, MATCH(A25, Demographics!A:A, 0)), "Unspecified Bank") -> GT Bank | O25: =IFERROR(INDEX(Demographics!H:H, MATCH(A25, Demographics!A:A, 0)) & "", "Unknown Status") -> Permanent
A26: 8a858eb05d2d1297015d313b03581809 | B26: 301999087 | C26: 2 | D26: 42943.682 | E26: 42943.64 | F26: 10000 | G26: 13000 | H26: 30 | J26: Good | K26: =(G26 - F26) / F26 -> 0.3 | L26: =IF(J26="bad", 1, 0) -> 0 | M26: =IF(C26=1, "1. First-Time Applicant", IF(C26<=3, "2. Early Repeat (2-3)", "3. High Velocity Loyalty (4+)")) -> 2. Early Repeat (2-3) | N26: =IFERROR(INDEX(Demographics!F:F, MATCH(A26, Demographics!A:A, 0)), "Unspecified Bank") -> GT Bank | O26: =IFERROR(INDEX(Demographics!H:H, MATCH(A26, Demographics!A:A, 0)) & "", "Unknown Status") -> Permanent
A27: 8a858eb85c1be44c015c1c4b667d25ee | B27: 301963210 | C27: 3 | D27: 42920.579 | E27: 42920.537 | F27: 10000 | G27: 13000 | H27: 30 | J27: Good | K27: =(G27 - F27) / F27 -> 0.3 | L27: =IF(J27="bad", 1, 0) -> 0 | M27: =IF(C27=1, "1. First-Time Applicant", IF(C27<=3, "2. Early Repeat (2-3)", "3. High Velocity Loyalty (4+)")) -> 2. Early Repeat (2-3) | N27: =IFERROR(INDEX(Demographics!F:F, MATCH(A27, Demographics!A:A, 0)), "Unspecified Bank") -> GT Bank | O27: =IFERROR(INDEX(Demographics!H:H, MATCH(A27, Demographics!A:A, 0)) & "", "Unknown Status") -> Permanent
A28: 8a858ec75bfd77c4015c0d841520351c | B28: 301959286 | C28: 4 | D28: 42917.776 | E28: 42917.734 | F28: 20000 | G28: 24500 | H28: 30 | J28: Good | K28: =(G28 - F28) / F28 -> 0.225 | L28: =IF(J28="bad", 1, 0) -> 0 | M28: =IF(C28=1, "1. First-Time Applicant", IF(C28<=3, "2. Early Repeat (2-3)", "3. High Velocity Loyalty (4+)")) -> 3. High Velocity Loyalty (4+) | N28: =IFERROR(INDEX(Demographics!F:F, MATCH(A28, Demographics!A:A, 0)), "Unspecified Bank") -> Union Bank | O28: =IFERROR(INDEX(Demographics!H:H, MATCH(A28, Demographics!A:A, 0)) & "", "Unknown Status") -> Permanent
A29: 8a858ed35cc5ce51015cc60f40f522b4 | B29: 301981535 | C29: 2 | D29: 42933.44 | E29: 42933.398 | F29: 10000 | G29: 11500 | H29: 15 | I29: 8a858edc59ee87640159eeb9774f1aa7 | J29: Good | K29: =(G29 - F29) / F29 -> 0.15 | L29: =IF(J29="bad", 1, 0) -> 0 | M29: =IF(C29=1, "1. First-Time Applicant", IF(C29<=3, "2. Early Repeat (2-3)", "3. High Velocity Loyalty (4+)")) -> 2. Early Repeat (2-3) | N29: =IFERROR(INDEX(Demographics!F:F, MATCH(A29, Demographics!A:A, 0)), "Unspecified Bank") -> GT Bank | O29: =IFERROR(INDEX(Demographics!H:H, MATCH(A29, Demographics!A:A, 0)) & "", "Unknown Status") -> Permanent
A30: 8a858edb5ad79cc6015ad7c9b29415c8 | B30: 301981500 | C30: 5 | D30: 42933.428 | E30: 42933.386 | F30: 20000 | G30: 22250 | H30: 15 | J30: Good | K30: =(G30 - F30) / F30 -> 0.1125 | L30: =IF(J30="bad", 1, 0) -> 0 | M30: =IF(C30=1, "1. First-Time Applicant", IF(C30<=3, "2. Early Repeat (2-3)", "3. High Velocity Loyalty (4+)")) -> 3. High Velocity Loyalty (4+) | N30: =IFERROR(INDEX(Demographics!F:F, MATCH(A30, Demographics!A:A, 0)), "Unspecified Bank") -> GT Bank | O30: =IFERROR(INDEX(Demographics!H:H, MATCH(A30, Demographics!A:A, 0)) & "", "Unknown Status") -> Permanent
A31: 8a858ee55830c4b90158337542ab18a1 | B31: 301972649 | C31: 6 | D31: 42927.395 | E31: 42927.352 | F31: 10000 | G31: 13000 | H31: 30 | J31: Bad | K31: =(G31 - F31) / F31 -> 0.3 | L31: =IF(J31="bad", 1, 0) -> 1 | M31: =IF(C31=1, "1. First-Time Applicant", IF(C31<=3, "2. Early Repeat (2-3)", "3. High Velocity Loyalty (4+)")) -> 3. High Velocity Loyalty (4+) | N31: =IFERROR(INDEX(Demographics!F:F, MATCH(A31, Demographics!A:A, 0)), "Unspecified Bank") -> Unspecified Bank | O31: =IFERROR(INDEX(Demographics!H:H, MATCH(A31, Demographics!A:A, 0)) & "", "Unknown Status") -> Unknown Status
A32: 8a858eec5ca21dcb015ca2493dee1e2d | B32: 301966278 | C32: 2 | D32: 42922.486 | E32: 42922.444 | F32: 10000 | G32: 13000 | H32: 30 | J32: Good | K32: =(G32 - F32) / F32 -> 0.3 | L32: =IF(J32="bad", 1, 0) -> 0 | M32: =IF(C32=1, "1. First-Time Applicant", IF(C32<=3, "2. Early Repeat (2-3)", "3. High Velocity Loyalty (4+)")) -> 2. Early Repeat (2-3) | N32: =IFERROR(INDEX(Demographics!F:F, MATCH(A32, Demographics!A:A, 0)), "Unspecified Bank") -> UBA | O32: =IFERROR(INDEX(Demographics!H:H, MATCH(A32, Demographics!A:A, 0)) & "", "Unknown Status") -> Permanent
A33: 8a858ef75997d0180159a695b01e2c4c | B33: 301989547 | C33: 5 | D33: 42937.656 | E33: 42937.614 | F33: 20000 | G33: 24500 | H33: 30 | J33: Good | K33: =(G33 - F33) / F33 -> 0.225 | L33: =IF(J33="bad", 1, 0) -> 0 | M33: =IF(C33=1, "1. First-Time Applicant", IF(C33<=3, "2. Early Repeat (2-3)", "3. High Velocity Loyalty (4+)")) -> 3. High Velocity Loyalty (4+) | N33: =IFERROR(INDEX(Demographics!F:F, MATCH(A33, Demographics!A:A, 0)), "Unspecified Bank") -> First Bank | O33: =IFERROR(INDEX(Demographics!H:H, MATCH(A33, Demographics!A:A, 0)) & "", "Unknown Status")
A34: 8a858f03582604ff0158260fcc730548 | B34: 302001370 | C34: 10 | D34: 42944.898 | E34: 42944.857 | F34: 20000 | G34: 24500 | H34: 30 | J34: Good | K34: =(G34 - F34) / F34 -> 0.225 | L34: =IF(J34="bad", 1, 0) -> 0 | M34: =IF(C34=1, "1. First-Time Applicant", IF(C34<=3, "2. Early Repeat (2-3)", "3. High Velocity Loyalty (4+)")) -> 3. High Velocity Loyalty (4+) | N34: =IFERROR(INDEX(Demographics!F:F, MATCH(A34, Demographics!A:A, 0)), "Unspecified Bank") -> First Bank | O34: =IFERROR(INDEX(Demographics!H:H, MATCH(A34, Demographics!A:A, 0)) & "", "Unknown Status") -> Permanent
A35: 8a858f085b905684015b906e73a01478 | B35: 302000465 | C35: 4 | D35: 42944.522 | E35: 42944.479 | F35: 20000 | G35: 24500 | H35: 30 | J35: Good | K35: =(G35 - F35) / F35 -> 0.225 | L35: =IF(J35="bad", 1, 0) -> 0 | M35: =IF(C35=1, "1. First-Time Applicant", IF(C35<=3, "2. Early Repeat (2-3)", "3. High Velocity Loyalty (4+)")) -> 3. High Velocity Loyalty (4+) | N35: =IFERROR(INDEX(Demographics!F:F, MATCH(A35, Demographics!A:A, 0)), "Unspecified Bank") -> FCMB | O35: =IFERROR(INDEX(Demographics!H:H, MATCH(A35, Demographics!A:A, 0)) & "", "Unknown Status") -> Permanent
A36: 8a858f1955b1c4df0155cd14c5b478ed | B36: 302000569 | C36: 2 | D36: 42944.554 | E36: 42944.511 | F36: 10000 | G36: 13000 | H36: 30 | J36: Good | K36: =(G36 - F36) / F36 -> 0.3 | L36: =IF(J36="bad", 1, 0) -> 0 | M36: =IF(C36=1, "1. First-Time Applicant", IF(C36<=3, "2. Early Repeat (2-3)", "3. High Velocity Loyalty (4+)")) -> 2. Early Repeat (2-3) | N36: =IFERROR(INDEX(Demographics!F:F, MATCH(A36, Demographics!A:A, 0)), "Unspecified Bank") -> Unspecified Bank | O36: =IFERROR(INDEX(Demographics!H:H, MATCH(A36, Demographics!A:A, 0)) & "", "Unknown Status") -> Unknown Status
A37: 8a858f2656e154de0156e3a87cdc45fb | B37: 301982122 | C37: 5 | D37: 42933.644 | E37: 42933.602 | F37: 20000 | G37: 22250 | H37: 15 | J37: Good | K37: =(G37 - F37) / F37 -> 0.1125 | L37: =IF(J37="bad", 1, 0) -> 0 | M37: =IF(C37=1, "1. First-Time Applicant", IF(C37<=3, "2. Early Repeat (2-3)", "3. High Velocity Loyalty (4+)")) -> 3. High Velocity Loyalty (4+) | N37: =IFERROR(INDEX(Demographics!F:F, MATCH(A37, Demographics!A:A, 0)), "Unspecified Bank") -> UBA | O37: =IFERROR(INDEX(Demographics!H:H, MATCH(A37, Demographics!A:A, 0)) & "", "Unknown Status") -> Student
A38: 8a858f2e5c699f3a015c6cf27a036477 | B38: 301959225 | C38: 2 | D38: 42917.738 | E38: 42917.696 | F38: 10000 | G38: 13000 | H38: 30 | I38: 8a858fc55b2548dd015b286e452c678c | J38: Good | K38: =(G38 - F38) / F38 -> 0.3 | L38: =IF(J38="bad", 1, 0) -> 0 | M38: =IF(C38=1, "1. First-Time Applicant", IF(C38<=3, "2. Early Repeat (2-3)", "3. High Velocity Loyalty (4+)")) -> 2. Early Repeat (2-3) | N38: =IFERROR(INDEX(Demographics!F:F, MATCH(A38, Demographics!A:A, 0)), "Unspecified Bank") -> UBA | O38: =IFERROR(INDEX(Demographics!H:H, MATCH(A38, Demographics!A:A, 0)) & "", "Unknown Status") -> Permanent
A39: 8a858f335cd0c78e015cd435d7192800 | B39: 301984674 | C39: 2 | D39: 42934.897 | E39: 42934.856 | F39: 10000 | G39: 11500 | H39: 15 | J39: Good | K39: =(G39 - F39) / F39 -> 0.15 | L39: =IF(J39="bad", 1, 0) -> 0 | M39: =IF(C39=1, "1. First-Time Applicant", IF(C39<=3, "2. Early Repeat (2-3)", "3. High Velocity Loyalty (4+)")) -> 2. Early Repeat (2-3) | N39: =IFERROR(INDEX(Demographics!F:F, MATCH(A39, Demographics!A:A, 0)), "Unspecified Bank") -> GT Bank | O39: =IFERROR(INDEX(Demographics!H:H, MATCH(A39, Demographics!A:A, 0)) & "", "Unknown Status") -> Permanent
A40: 8a858f3d5add42e2015ae0ca6cb66b83 | B40: 301998400 | C40: 8 | D40: 42943.399 | E40: 42943.357 | F40: 30000 | G40: 34500 | H40: 30 | J40: Good | K40: =(G40 - F40) / F40 -> 0.15 | L40: =IF(J40="bad", 1, 0) -> 0 | M40: =IF(C40=1, "1. First-Time Applicant", IF(C40<=3, "2. Early Repeat (2-3)", "3. High Velocity Loyalty (4+)")) -> 3. High Velocity Loyalty (4+) | N40: =IFERROR(INDEX(Demographics!F:F, MATCH(A40, Demographics!A:A, 0)), "Unspecified Bank") -> Unspecified Bank | O40: =IFERROR(INDEX(Demographics!H:H, MATCH(A40, Demographics!A:A, 0)) & "", "Unknown Status") -> Unknown Status
A41: 8a858f4655ca643c0155cbc4e13945cc | B41: 301965090 | C41: 15 | D41: 42921.658 | E41: 42921.616 | F41: 40000 | G41: 44000 | H41: 30 | J41: Good | K41: =(G41 - F41) / F41 -> 0.1 | L41: =IF(J41="bad", 1, 0) -> 0 | M41: =IF(C41=1, "1. First-Time Applicant", IF(C41<=3, "2. Early Repeat (2-3)", "3. High Velocity Loyalty (4+)")) -> 3. High Velocity Loyalty (4+) | N41: =IFERROR(INDEX(Demographics!F:F, MATCH(A41, Demographics!A:A, 0)), "Unspecified Bank") -> GT Bank | O41: =IFERROR(INDEX(Demographics!H:H, MATCH(A41, Demographics!A:A, 0)) & "", "Unknown Status") -> Permanent
A42: 8a858f4f5511dca201551b73634170b6 | B42: 301997295 | C42: 4 | D42: 42942.677 | E42: 42942.636 | F42: 10000 | G42: 13000 | H42: 30 | J42: Good | K42: =(G42 - F42) / F42 -> 0.3 | L42: =IF(J42="bad", 1, 0) -> 0 | M42: =IF(C42=1, "1. First-Time Applicant", IF(C42<=3, "2. Early Repeat (2-3)", "3. High Velocity Loyalty (4+)")) -> 3. High Velocity Loyalty (4+) | N42: =IFERROR(INDEX(Demographics!F:F, MATCH(A42, Demographics!A:A, 0)), "Unspecified Bank") -> Unspecified Bank | O42: =IFERROR(INDEX(Demographics!H:H, MATCH(A42, Demographics!A:A, 0)) & "", "Unknown Status") -> Unknown Status
A43: 8a858f555cc65d60015cc72de106320c | B43: 301974694 | C43: 2 | D43: 42928.602 | E43: 42928.56 | F43: 10000 | G43: 13000 | H43: 30 | I43: 8a858e6c5c88d145015c89430ef61a5d | J43: Good | K43: =(G43 - F43) / F43 -> 0.3 | L43: =IF(J43="bad", 1, 0) -> 0 | M43: =IF(C43=1, "1. First-Time Applicant", IF(C43<=3, "2. Early Repeat (2-3)", "3. High Velocity Loyalty (4+)")) -> 2. Early Repeat (2-3) | N43: =IFERROR(INDEX(Demographics!F:F, MATCH(A43, Demographics!A:A, 0)), "Unspecified Bank") -> Unspecified Bank | O43: =IFERROR(INDEX(Demographics!H:H, MATCH(A43, Demographics!A:A, 0)) & "", "Unknown Status") -> Unknown Status
A44: 8a858f5e599783c0015997c56ef70ffa | B44: 302001086 | C44: 3 | D44: 42944.753 | E44: 42944.71 | F44: 10000 | G44: 11500 | H44: 15 | J44: Good | K44: =(G44 - F44) / F44 -> 0.15 | L44: =IF(J44="bad", 1, 0) -> 0 | M44: =IF(C44=1, "1. First-Time Applicant", IF(C44<=3, "2. Early Repeat (2-3)", "3. High Velocity Loyalty (4+)")) -> 2. Early Repeat (2-3) | N44: =IFERROR(INDEX(Demographics!F:F, MATCH(A44, Demographics!A:A, 0)), "Unspecified Bank") -> GT Bank | O44: =IFERROR(INDEX(Demographics!H:H, MATCH(A44, Demographics!A:A, 0)) & "", "Unknown Status")
...

Sheet Sheet4

Sheet Demographics
A1: customerid | B1: birthdate | C1: bank_account_type | D1: longitude_gps | E1: latitude_gps | F1: bank_name_clients | G1: bank_branch_clients | H1: employment_status_clients | I1: level_of_education_clients
A2: 8a858e135cb22031015cbafc76964ebd | B2: 26947 | C2: Savings | D2: 3.319219 | E2: 6.5286039 | F2: GT Bank
A3: 8a858e275c7ea5ec015c82482d7c3996 | B3: 31433 | C3: Savings | D3: 3.3255983 | E3: 7.1194033 | F3: Sterling Bank | H3: Permanent
A4: 8a858e5b5bd99460015bdc95cd485634 | B4: 31868 | C4: Savings | D4: 5.7460998 | E4: 5.5631737 | F4: Fidelity Bank
A5: 8a858efd5ca70688015cabd1f1e94b55 | B5: 33438 | C5: Savings | D5: 3.3628497 | E5: 6.6424853 | F5: GT Bank | H5: Permanent
A6: 8a858e785acd3412015acd48f4920d04 | B6: 30277 | C6: Savings | D6: 8.4553317 | E6: 11.97141 | F6: GT Bank | H6: Permanent
A7: 8a858f045bc9690c015bca251e9a4e95 | B7: 28835 | C7: Savings | D7: 3.3300869 | E7: 6.5525177 | F7: GT Bank | H7: Permanent
A8: 8a858ea05a859123015a8892914d15b7 | B8: 33075 | C8: Savings | D8: 3.365935 | E8: 6.5648233 | F8: Access Bank | H8: Permanent
A9: 8a858f275c451af5015c546a50ce55ed | B9: 31664 | C9: Savings | D9: 4.734382 | E9: 7.6068678 | F9: GT Bank | H9: Permanent
A10: 8a858f405d13c45f015d13dd93ec0c1c | B10: 33925 | C10: Savings | D10: 3.2905898 | E10: 6.6120747 | F10: EcoBank | H10: Permanent
A11: 8a858f735c161bda015c164d86632026 | B11: 23796 | C11: Savings | D11: 3.3627834 | E11: 6.5094178 | F11: EcoBank | H11: Permanent
A12: 8a858f2a5ce989dd015ce9fc24b1474b | B12: 34679 | C12: Savings | D12: 3.3502377 | E12: 7.1381618 | F12: FCMB
A13: 8a858f3a5c10828d015c109746d20aee | B13: 25768 | C13: Savings | D13: 5.768004 | E13: 5.559055 | F13: Skye Bank | H13: Permanent
A14: 8a858fb4563228d201564fd7519f22a8 | B14: 34488 | C14: Other | D14: 3.3810932 | E14: 6.608266 | F14: UBA | H14: Student | I14: Secondary
A15: 8a858e9d59e0997b0159eae2e4fa7611 | B15: 32472 | C15: Savings | D15: 3.3725099 | E15: 6.5181154 | F15: Zenith Bank
A16: 8a858f955a61ad4e015a69ee1edd0d3d | B16: 31517 | C16: Savings | D16: 3.357961 | E16: 6.5125169 | F16: GT Bank | H16: Permanent
A17: 8a858ff25a6a19ee015a6abff5ed659c | B17: 32499 | C17: Savings | D17: 7.5078362 | E17: 9.0483723 | F17: EcoBank | H17: Permanent
A18: 8a858e6c5c88d145015c894de1a91c5c | B18: 32255 | C18: Savings | D18: 3.363275 | E18: 7.1455067 | F18: GT Bank | H18: Permanent
A19: 8a858eb45876dcc501587dae11f2283e | B19: 32574 | C19: Savings | D19: 6.9744361 | E19: 4.8113433 | F19: Access Bank | H19: Permanent
A20: 8a858f2f54e28d530154ecdd303004fa | B20: 30444 | C20: Savings | D20: 3.4784832 | E20: 6.4420013 | F20: Diamond Bank | G20: LAGOS | H20: Permanent | I20: Graduate
A21: 8a858fef570f30e501571fd446d44c81 | B21: 31860 | C21: Savings | D21: 4.5684069 | E21: 7.5039585 | F21: GT Bank | H21: Self-Employed
A22: 8a858f6c570f2d660157238b0c4a1bdd | B22: 33057 | C22: Other | D22: 7.0408905 | E22: 5.7946838 | F22: Zenith Bank | H22: Self-Employed | I22: Graduate
A23: 8a85893d542e18bc01542e37365c120a | B23: 32161 | C23: Savings | D23: 3.3639265 | E23: 7.1380483 | F23: Zenith Bank | H23: Permanent | I23: Graduate
A24: 8a8588f35438fe12015444567666018e | B24: 30943 | C24: Other | D24: 11.13935 | E24: 10.292041 | F24: EcoBank | H24: Permanent
A25: 8a858f275c451af5015c49a2c43b5fb2 | B25: 31343 | C25: Savings | D25: 3.2987679 | E25: 6.6817293 | F25: Sterling Bank | H25: Permanent
A26: 8a858e045cd5b1d6015cd9c070a212a5 | B26: 31316 | C26: Savings | D26: 7.9028957 | E26: 8.8497435 | F26: UBA
A27: 8a858e2155defefd0155e12953ee00a1 | B27: 32668 | C27: Other | D27: 8.00851 | E27: 4.54539 | F27: First Bank | H27: Permanent | I27: Graduate
A28: 8a858e4b5a7f868b015a80f3822d505b | B28: 31992 | C28: Savings | D28: 3.3920645 | E28: 6.5083683 | F28: GT Bank | H28: Permanent
A29: 8a858f0056b7cf8e0156bbeefc4933cc | B29: 29593 | C29: Other | D29: 3.2943641 | E29: 6.5457472 | F29: EcoBank | H29: Self-Employed
A30: 8a858f0e5a6171ba015a648137c361bc | B30: 34218 | C30: Savings | D30: 3.385065 | E30: 6.5659733 | F30: GT Bank | H30: Permanent
A31: 8a858f125c5f88b1015c603d2810428c | B31: 30791 | C31: Savings | D31: 7.0481835 | E31: 4.8426899 | F31: GT Bank | H31: Permanent
A32: 8a858ee75a6156c0015a635f394a5f79 | B32: 30172 | C32: Savings | D32: 3.9395519 | E32: 7.4118193 | F32: Access Bank | H32: Permanent
A33: 8a858eed5af07cc4015af10da7565173 | B33: 27963 | C33: Savings | D33: 3.3553398 | E33: 6.5125031 | F33: GT Bank | H33: Permanent
A34: 8a858f445d41ebbe015d50c105334acc | B34: 31765 | C34: Savings | D34: 3.2148502 | E34: 6.538267 | F34: GT Bank
A35: 8a858f285d3ca5c4015d3cbb1f94073a | B35: 28335 | C35: Current | D35: 7.0358424 | E35: 4.8050149 | F35: GT Bank | H35: Permanent
A36: 8a858f225bfdb280015c108bf6f53281 | B36: 32057 | C36: Savings | D36: 3.3343336 | E36: 6.5223702 | F36: Union Bank | H36: Permanent
A37: 8a858f6c5cac8f53015cafeb15141be1 | B37: 33905 | C37: Savings | D37: 3.359517 | E37: 6.6106167 | F37: GT Bank | H37: Permanent
A38: 8a858f675c1c43bc015c2049f2d20224 | B38: 28019 | C38: Savings | D38: 3.4280578 | E38: 6.4323651 | F38: Access Bank | H38: Permanent
A39: 8a858f7e564ad338015654d3a5c242a5 | B39: 32282 | C39: Other | D39: 8.6713276 | E39: 9.0830135 | F39: GT Bank | H39: Permanent
A40: 8a858e165b90faf9015b9a873738471e | B40: 31922 | C40: Savings | D40: 3.9739724 | E40: 7.3727483 | F40: Access Bank | H40: Permanent
...
